Workbook

Sheet RAW_DATA
A1: Order ID | B1: Customer ID | C1: Product Category | D1: SKU | E1: Order Date | F1: Delivery Date | G1: Region | H1: Sales Amount (NPR) | I1: Discount Applied (%) | J1: Return Status
A2: ORD-100001 | B2: CUST-2424 | C2: Women | D2: WOM-KURTA-001 | E2: 2024-02-22 | F2: 2024-02-29 | G2: Lumbini | H2: 3736.56 | I2: 5 | J2: No
A3: ORD-100002 | B3: CUST-9928 | C3: Women | D3: WOM-KURTA-001 | E3: 2024-11-04 | F3: 2024-11-05 | G3: Bagmati | H3: 3873.58 | I3: 5 | J3: No
A4: ORD-100003 | B4: CUST-3547 | C4: Women | D4: WOM-SUIT-001 | E4: 2024-03-22 | F4: 2024-03-29 | G4: Gandaki | H4: 13104.85 | I4: 30 | J4: No
A5: ORD-100004 | B5: CUST-8527 | C5: Men | D5: MEN-SUIT-001 | E5: 2024-06-25 | F5: 2024-07-01 | G5: Bagmati | H5: 1902.39 | I5: 15 | J5: No
A6: ORD-100005 | B6: CUST-4150 | C6: Women | D6: WOM-LEHENGA-001 | E6: 2024-11-12 | F6: 2024-11-22 | G6: Bagmati | H6: 12526.37 | I6: 10 | J6: No
A7: ORD-100006 | B7: CUST-7227 | C7: Women | D7: WOM-KURTA-001 | E7: 2024-02-10 | F7: 2024-02-20 | G7: Lumbini | H7: 4696.13 | I7: 30 | J7: No
A8: ORD-100007 | B8: CUST-2169 | C8: Men | D8: MEN-SUIT-001 | E8: 2024-05-16 | F8: 2024-05-23 | G8: Bagmati | H8: 3537.85 | I8: 10 | J8: No
A9: ORD-100008 | B9: CUST-4598 | C9: Women | D9: WOM-DRESS-001 | E9: 2024-07-13 | F9: 2024-07-17 | G9: Gandaki | H9: 2869.34 | I9: 5 | J9: No
A10: ORD-100009 | B10: CUST-6155 | C10: Women | D10: WOM-KURTA-001 | E10: 2024-07-24 | F10: 2024-07-28 | G10: Bagmati | H10: 12173.16 | I10: 0 | J10: No
A11: ORD-100010 | B11: CUST-9830 | C11: Men | D11: MEN-TSHIRT-001 | E11: 2024-05-15 | F11: 2024-05-18 | G11: Madhesh | H11: 7153.35 | I11: 25 | J11: No
A12: ORD-100011 | B12: CUST-9085 | C12: Men | D12: MEN-KURTA-001 | E12: 2024-04-22 | F12: 2024-05-07 | G12: Madhesh | H12: 6291.31 | I12: 20 | J12: Yes
A13: ORD-100012 | B13: CUST-7252 | C13: Men | D13: MEN-SHIRT-001 | E13: 2024-12-14 | F13: 2024-12-19 | G13: Karnali | H13: 9597.97 | I13: 5 | J13: Yes
... A5001: ORD-105000 | B5001: CUST-2511 | C5001: Women | D5001: WOM-SAREE-001 | E5001: 2024-08-23 | F5001: 2024-08-30 | G5001: Gandaki | H5001: 6335.14 | I5001: 30 | J5001: No

Sheet CALCULATIONS
A1: ASSUMPTIONS
A2: Base Cost % | B2: 0.6
A3: Return Extra Cost % | B3: 0.2
A5: Order ID | B5: Customer ID | C5: Product Category | D5: SKU | E5: Order Date | F5: Delivery Date | G5: Region | H5: Sales Amount | I5: Discount % | J5: Return Status | K5: Delivery Days | L5: Effective Revenue | M5: Base Cost | N5: Return Cost | O5: True Profit | P5: Profit Margin %
A6: =RAW_DATA!A2 -> ORD-100001 | B6: =RAW_DATA!B2 -> CUST-2424 | C6: =RAW_DATA!C2 -> Women | D6: =RAW_DATA!D2 -> WOM-KURTA-001 | E6: =RAW_DATA!E2 -> 2024-02-22 | F6: =RAW_DATA!F2 -> 2024-02-29 | G6: =RAW_DATA!G2 -> Lumbini | H6: =RAW_DATA!H2 -> 3736.56 | ... J6: =RAW_DATA!J2 -> No | K6: =IF(AND(F6<>"",E6<>""),DATEVALUE(F6)-DATEVALUE(E6),"") -> 7 | L6: =H6*(1-I6/100) -> 3549.732 | M6: =H6*CALCULATIONS!$B$2 -> 2241.936 | N6: =IF(J6="Yes",H6*CALCULATIONS!$B$3,0) -> 0 | O6: =L6-M6-N6 -> 1307.796 | P6: =IF(L6>0,O6/L6,"") -> 0.36842105
A7: =RAW_DATA!A3 -> ORD-100002 | B7: =RAW_DATA!B3 -> CUST-9928 | C7: =RAW_DATA!C3 -> Women | D7: =RAW_DATA!D3 -> WOM-KURTA-001 | E7: =RAW_DATA!E3 -> 2024-11-04 | F7: =RAW_DATA!F3 -> 2024-11-05 | G7: =RAW_DATA!G3 -> Bagmati | H7: =RAW_DATA!H3 -> 3873.58 | ... J7: =RAW_DATA!J3 -> No | K7: =IF(AND(F7<>"",E7<>""),DATEVALUE(F7)-DATEVALUE(E7),"") -> 1 | L7: =H7*(1-I7/100) -> 3679.901 | M7: =H7*CALCULATIONS!$B$2 -> 2324.148 | N7: =IF(J7="Yes",H7*CALCULATIONS!$B$3,0) -> 0 | O7: =L7-M7-N7 -> 1355.753 | P7: =IF(L7>0,O7/L7,"") -> 0.36842105
A8: =RAW_DATA!A4 -> ORD-100003 | B8: =RAW_DATA!B4 -> CUST-3547 | C8: =RAW_DATA!C4 -> Women | D8: =RAW_DATA!D4 -> WOM-SUIT-001 | E8: =RAW_DATA!E4 -> 2024-03-22 | F8: =RAW_DATA!F4 -> 2024-03-29 | G8: =RAW_DATA!G4 -> Gandaki | H8: =RAW_DATA!H4 -> 13104.85 | ... J8: =RAW_DATA!J4 -> No | K8: =IF(AND(F8<>"",E8<>""),DATEVALUE(F8)-DATEVALUE(E8),"") -> 7 | L8: =H8*(1-I8/100) -> 9173.395 | M8: =H8*CALCULATIONS!$B$2 -> 7862.91 | N8: =IF(J8="Yes",H8*CALCULATIONS!$B$3,0) -> 0 | O8: =L8-M8-N8 -> 1310.485 | P8: =IF(L8>0,O8/L8,"") -> 0.14285714
A9: =RAW_DATA!A5 -> ORD-100004 | B9: =RAW_DATA!B5 -> CUST-8527 | C9: =RAW_DATA!C5 -> Men | D9: =RAW_DATA!D5 -> MEN-SUIT-001 | E9: =RAW_DATA!E5 -> 2024-06-25 | F9: =RAW_DATA!F5 -> 2024-07-01 | G9: =RAW_DATA!G5 -> Bagmati | H9: =RAW_DATA!H5 -> 1902.39 | ... J9: =RAW_DATA!J5 -> No | K9: =IF(AND(F9<>"",E9<>""),DATEVALUE(F9)-DATEVALUE(E9),"") -> 6 | L9: =H9*(1-I9/100) -> 1617.0315 | M9: =H9*CALCULATIONS!$B$2 -> 1141.434 | N9: =IF(J9="Yes",H9*CALCULATIONS!$B$3,0) -> 0 | O9: =L9-M9-N9 -> 475.5975 | P9: =IF(L9>0,O9/L9,"") -> 0.29411765
A10: =RAW_DATA!A6 -> ORD-100005 | B10: =RAW_DATA!B6 -> CUST-4150 | C10: =RAW_DATA!C6 -> Women | D10: =RAW_DATA!D6 -> WOM-LEHENGA-001 | E10: =RAW_DATA!E6 -> 2024-11-12 | F10: =RAW_DATA!F6 -> 2024-11-22 | G10: =RAW_DATA!G6 -> Bagmati | H10: =RAW_DATA!H6 -> 12526.37 | ... J10: =RAW_DATA!J6 -> No | K10: =IF(AND(F10<>"",E10<>""),DATEVALUE(F10)-DATEVALUE(E10),"") -> 10 | L10: =H10*(1-I10/100) -> 11273.733 | M10: =H10*CALCULATIONS!$B$2 -> 7515.822 | N10: =IF(J10="Yes",H10*CALCULATIONS!$B$3,0) -> 0 | O10: =L10-M10-N10 -> 3757.911 | P10: =IF(L10>0,O10/L10,"") -> 0.33333333
A11: =RAW_DATA!A7 -> ORD-100006 | B11: =RAW_DATA!B7 -> CUST-7227 | C11: =RAW_DATA!C7 -> Women | D11: =RAW_DATA!D7 -> WOM-KURTA-001 | E11: =RAW_DATA!E7 -> 2024-02-10 | F11: =RAW_DATA!F7 -> 2024-02-20 | G11: =RAW_DATA!G7 -> Lumbini | H11: =RAW_DATA!H7 -> 4696.13 | ... J11: =RAW_DATA!J7 -> No | K11: =IF(AND(F11<>"",E11<>""),DATEVALUE(F11)-DATEVALUE(E11),"") -> 10 | L11: =H11*(1-I11/100) -> 3287.291 | M11: =H11*CALCULATIONS!$B$2 -> 2817.678 | N11: =IF(J11="Yes",H11*CALCULATIONS!$B$3,0) -> 0 | O11: =L11-M11-N11 -> 469.613 | P11: =IF(L11>0,O11/L11,"") -> 0.14285714
A12: =RAW_DATA!A8 -> ORD-100007 | B12: =RAW_DATA!B8 -> CUST-2169 | C12: =RAW_DATA!C8 -> Men | D12: =RAW_DATA!D8 -> MEN-SUIT-001 | E12: =RAW_DATA!E8 -> 2024-05-16 | F12: =RAW_DATA!F8 -> 2024-05-23 | G12: =RAW_DATA!G8 -> Bagmati | H12: =RAW_DATA!H8 -> 3537.85 | ... J12: =RAW_DATA!J8 -> No | K12: =IF(AND(F12<>"",E12<>""),DATEVALUE(F12)-DATEVALUE(E12),"") -> 7 | L12: =H12*(1-I12/100) -> 3184.065 | M12: =H12*CALCULATIONS!$B$2 -> 2122.71 | N12: =IF(J12="Yes",H12*CALCULATIONS!$B$3,0) -> 0 | O12: =L12-M12-N12 -> 1061.355 | P12: =IF(L12>0,O12/L12,"") -> 0.33333333
A13: =RAW_DATA!A9 -> ORD-100008 | B13: =RAW_DATA!B9 -> CUST-4598 | C13: =RAW_DATA!C9 -> Women | D13: =RAW_DATA!D9 -> WOM-DRESS-001 | E13: =RAW_DATA!E9 -> 2024-07-13 | F13: =RAW_DATA!F9 -> 2024-07-17 | G13: =RAW_DATA!G9 -> Gandaki | H13: =RAW_DATA!H9 -> 2869.34 | ... J13: =RAW_DATA!J9 -> No | K13: =IF(AND(F13<>"",E13<>""),DATEVALUE(F13)-DATEVALUE(E13),"") -> 4 | L13: =H13*(1-I13/100) -> 2725.873 | M13: =H13*CALCULATIONS!$B$2 -> 1721.604 | N13: =IF(J13="Yes",H13*CALCULATIONS!$B$3,0) -> 0 | O13: =L13-M13-N13 -> 1004.269 | P13: =IF(L13>0,O13/L13,"") -> 0.36842105
A14: =RAW_DATA!A10 -> ORD-100009 | B14: =RAW_DATA!B10 -> CUST-6155 | C14: =RAW_DATA!C10 -> Women | D14: =RAW_DATA!D10 -> WOM-KURTA-001 | E14: =RAW_DATA!E10 -> 2024-07-24 | F14: =RAW_DATA!F10 -> 2024-07-28 | G14: =RAW_DATA!G10 -> Bagmati | H14: =RAW_DATA!H10 -> 12173.16 | ... J14: =RAW_DATA!J10 -> No | K14: =IF(AND(F14<>"",E14<>""),DATEVALUE(F14)-DATEVALUE(E14),"") -> 4 | L14: =H14*(1-I14/100) -> 12173.16 | M14: =H14*CALCULATIONS!$B$2 -> 7303.896 | N14: =IF(J14="Yes",H14*CALCULATIONS!$B$3,0) -> 0 | O14: =L14-M14-N14 -> 4869.264 | P14: =IF(L14>0,O14/L14,"") -> 0.4
A15: =RAW_DATA!A11 -> ORD-100010 | B15: =RAW_DATA!B11 -> CUST-9830 | C15: =RAW_DATA!C11 -> Men | D15: =RAW_DATA!D11 -> MEN-TSHIRT-001 | E15: =RAW_DATA!E11 -> 2024-05-15 | F15: =RAW_DATA!F11 -> 2024-05-18 | G15: =RAW_DATA!G11 -> Madhesh | H15: =RAW_DATA!H11 -> 7153.35 | ... J15: =RAW_DATA!J11 -> No | K15: =IF(AND(F15<>"",E15<>""),DATEVALUE(F15)-DATEVALUE(E15),"") -> 3 | L15: =H15*(1-I15/100) -> 5365.0125 | M15: =H15*CALCULATIONS!$B$2 -> 4292.01 | N15: =IF(J15="Yes",H15*CALCULATIONS!$B$3,0) -> 0 | O15: =L15-M15-N15 -> 1073.0025 | P15: =IF(L15>0,O15/L15,"") -> 0.2
A16: =RAW_DATA!A12 -> ORD-100011 | B16: =RAW_DATA!B12 -> CUST-9085 | C16: =RAW_DATA!C12 -> Men | D16: =RAW_DATA!D12 -> MEN-KURTA-001 | E16: =RAW_DATA!E12 -> 2024-04-22 | F16: =RAW_DATA!F12 -> 2024-05-07 | G16: =RAW_DATA!G12 -> Madhesh | H16: =RAW_DATA!H12 -> 6291.31 | ... J16: =RAW_DATA!J12 -> Yes | K16: =IF(AND(F16<>"",E16<>""),DATEVALUE(F16)-DATEVALUE(E16),"") -> 15 | L16: =H16*(1-I16/100) -> 5033.048 | M16: =H16*CALCULATIONS!$B$2 -> 3774.786 | N16: =IF(J16="Yes",H16*CALCULATIONS!$B$3,0) -> 1258.262 | O16: =L16-M16-N16 -> 0 | P16: =IF(L16>0,O16/L16,"") -> 0
A17: =RAW_DATA!A13 -> ORD-100012 | B17: =RAW_DATA!B13 -> CUST-7252 | C17: =RAW_DATA!C13 -> Men | D17: =RAW_DATA!D13 -> MEN-SHIRT-001 | E17: =RAW_DATA!E13 -> 2024-12-14 | F17: =RAW_DATA!F13 -> 2024-12-19 | G17: =RAW_DATA!G13 -> Karnali | H17: =RAW_DATA!H13 -> 9597.97 | ... J17: =RAW_DATA!J13 -> Yes | K17: =IF(AND(F17<>"",E17<>""),DATEVALUE(F17)-DATEVALUE(E17),"") -> 5 | L17: =H17*(1-I17/100) -> 9118.0715 | M17: =H17*CALCULATIONS!$B$2 -> 5758.782 | N17: =IF(J17="Yes",H17*CALCULATIONS!$B$3,0) -> 1919.594 | O17: =L17-M17-N17 -> 1439.6955 | P17: =IF(L17>0,O17/L17,"") -> 0.15789474
... A5005: =RAW_DATA!A5001 -> ORD-105000 | B5005: =RAW_DATA!B5001 -> CUST-2511 | C5005: =RAW_DATA!C5001 -> Women | D5005: =RAW_DATA!D5001 -> WOM-SAREE-001 | E5005: =RAW_DATA!E5001 -> 2024-08-23 | F5005: =RAW_DATA!F5001 -> 2024-08-30 | G5005: =RAW_DATA!G5001 -> Gandaki | H5005: =RAW_DATA!H5001 -> 6335.14 | ... J5005: =RAW_DATA!J5001 -> No | K5005: =IF(AND(F5005<>"",E5005<>""),DATEVALUE(F5005)-DATEVALUE(E5005),"") -> 7 | L5005: =H5005*(1-I5005/100) -> 4434.598 | M5005: =H5005*CALCULATIONS!$B$2 -> 3801.084 | N5005: =IF(J5005="Yes",H5005*CALCULATIONS!$B$3,0) -> 0 | O5005: =L5005-M5005-N5005 -> 633.514 | P5005: =IF(L5005>0,O5005/L5005,"") -> 0.14285714

Sheet PIVOT_DATA
A1: P1: MONTHLY PROFIT BY CATEGORY (NPR)
A2: Month | B2: Month# | C2: Men | D2: Women | E2: Kids | F2: Total
A3: Jan | B3: 1 | C3: =SUMPRODUCT((MONTH(DATEVALUE(CALCULATIONS!E6:E5005))=B3)*(CALCULATIONS!C6:C5005="Men")*(CALCULATIONS!O6:O5005)) -> 262566.42 | D3: =SUMPRODUCT((MONTH(DATEVALUE(CALCULATIONS!E6:E5005))=B3)*(CALCULATIONS!C6:C5005="Women")*(CALCULATIONS!O6:O5005)) -> 272034.54 | E3: =SUMPRODUCT((MONTH(DATEVALUE(CALCULATIONS!E6:E5005))=B3)*(CALCULATIONS!C6:C5005="Kids")*(CALCULATIONS!O6:O5005)) -> 133339.69 | F3: =SUM(C3:E3) -> 667940.65
A4: Feb | B4: 2 | C4: =SUMPRODUCT((MONTH(DATEVALUE(CALCULATIONS!E6:E5005))=B4)*(CALCULATIONS!C6:C5005="Men")*(CALCULATIONS!O6:O5005)) -> 284157.46 | D4: =SUMPRODUCT((MONTH(DATEVALUE(CALCULATIONS!E6:E5005))=B4)*(CALCULATIONS!C6:C5005="Women")*(CALCULATIONS!O6:O5005)) -> 280479.8 | E4: =SUMPRODUCT((MONTH(DATEVALUE(CALCULATIONS!E6:E5005))=B4)*(CALCULATIONS!C6:C5005="Kids")*(CALCULATIONS!O6:O5005)) -> 122271.79 | F4: =SUM(C4:E4) -> 686909.05
A5: Mar | B5: 3 | C5: =SUMPRODUCT((MONTH(DATEVALUE(CALCULATIONS!E6:E5005))=B5)*(CALCULATIONS!C6:C5005="Men")*(CALCULATIONS!O6:O5005)) -> 286144.58 | D5: =SUMPRODUCT((MONTH(DATEVALUE(CALCULATIONS!E6:E5005))=B5)*(CALCULATIONS!C6:C5005="Women")*(CALCULATIONS!O6:O5005)) -> 281468.46 | E5: =SUMPRODUCT((MONTH(DATEVALUE(CALCULATIONS!E6:E5005))=B5)*(CALCULATIONS!C6:C5005="Kids")*(CALCULATIONS!O6:O5005)) -> 151507.77 | F5: =SUM(C5:E5) -> 719120.81
A6: Apr | B6: 4 | C6: =SUMPRODUCT((MONTH(DATEVALUE(CALCULATIONS!E6:E5005))=B6)*(CALCULATIONS!C6:C5005="Men")*(CALCULATIONS!O6:O5005)) -> 235373.27 | D6: =SUMPRODUCT((MONTH(DATEVALUE(CALCULATIONS!E6:E5005))=B6)*(CALCULATIONS!C6:C5005="Women")*(CALCULATIONS!O6:O5005)) -> 249010.28 | E6: =SUMPRODUCT((MONTH(DATEVALUE(CALCULATIONS!E6:E5005))=B6)*(CALCULATIONS!C6:C5005="Kids")*(CALCULATIONS!O6:O5005)) -> 101519.94 | F6: =SUM(C6:E6) -> 585903.49
A7: May | B7: 5 | C7: =SUMPRODUCT((MONTH(DATEVALUE(CALCULATIONS!E6:E5005))=B7)*(CALCULATIONS!C6:C5005="Men")*(CALCULATIONS!O6:O5005)) -> 260362.18 | D7: =SUMPRODUCT((MONTH(DATEVALUE(CALCULATIONS!E6:E5005))=B7)*(CALCULATIONS!C6:C5005="Women")*(CALCULATIONS!O6:O5005)) -> 285885.12 | E7: =SUMPRODUCT((MONTH(DATEVALUE(CALCULATIONS!E6:E5005))=B7)*(CALCULATIONS!C6:C5005="Kids")*(CALCULATIONS!O6:O5005)) -> 164473.71 | F7: =SUM(C7:E7) -> 710721.01
A8: Jun | B8: 6 | C8: =SUMPRODUCT((MONTH(DATEVALUE(CALCULATIONS!E6:E5005))=B8)*(CALCULATIONS!C6:C5005="Men")*(CALCULATIONS!O6:O5005)) -> 261906.92 | D8: =SUMPRODUCT((MONTH(DATEVALUE(CALCULATIONS!E6:E5005))=B8)*(CALCULATIONS!C6:C5005="Women")*(CALCULATIONS!O6:O5005)) -> 283600.75 | E8: =SUMPRODUCT((MONTH(DATEVALUE(CALCULATIONS!E6:E5005))=B8)*(CALCULATIONS!C6:C5005="Kids")*(CALCULATIONS!O6:O5005)) -> 129274.41 | F8: =SUM(C8:E8) -> 674782.08
A9: Jul | B9: 7 | C9: =SUMPRODUCT((MONTH(DATEVALUE(CALCULATIONS!E6:E5005))=B9)*(CALCULATIONS!C6:C5005="Men")*(CALCULATIONS!O6:O5005)) -> 325340.9 | D9: =SUMPRODUCT((MONTH(DATEVALUE(CALCULATIONS!E6:E5005))=B9)*(CALCULATIONS!C6:C5005="Women")*(CALCULATIONS!O6:O5005)) -> 290574.24 | E9: =SUMPRODUCT((MONTH(DATEVALUE(CALCULATIONS!E6:E5005))=B9)*(CALCULATIONS!C6:C5005="Kids")*(CALCULATIONS!O6:O5005)) -> 171872.71 | F9: =SUM(C9:E9) -> 787787.85
A10: Aug | B10: 8 | C10: =SUMPRODUCT((MONTH(DATEVALUE(CALCULATIONS!E6:E5005))=B10)*(CALCULATIONS!C6:C5005="Men")*(CALCULATIONS!O6:O5005)) -> 295694.59 | D10: =SUMPRODUCT((MONTH(DATEVALUE(CALCULATIONS!E6:E5005))=B10)*(CALCULATIONS!C6:C5005="Women")*(CALCULATIONS!O6:O5005)) -> 295161.99 | E10: =SUMPRODUCT((MONTH(DATEVALUE(CALCULATIONS!E6:E5005))=B10)*(CALCULATIONS!C6:C5005="Kids")*(CALCULATIONS!O6:O5005)) -> 119492.58 | F10: =SUM(C10:E10) -> 710349.16
A11: Sep | B11: 9 | C11: =SUMPRODUCT((MONTH(DATEVALUE(CALCULATIONS!E6:E5005))=B11)*(CALCULATIONS!C6:C5005="Men")*(CALCULATIONS!O6:O5005)) -> 239569.31 | D11: =SUMPRODUCT((MONTH(DATEVALUE(CALCULATIONS!E6:E5005))=B11)*(CALCULATIONS!C6:C5005="Women")*(CALCULATIONS!O6:O5005)) -> 240357.1 | E11: =SUMPRODUCT((MONTH(DATEVALUE(CALCULATIONS!E6:E5005))=B11)*(CALCULATIONS!C6:C5005="Kids")*(CALCULATIONS!O6:O5005)) -> 102776.74 | F11: =SUM(C11:E11) -> 582703.15
A12: Oct | B12: 10 | C12: =SUMPRODUCT((MONTH(DATEVALUE(CALCULATIONS!E6:E5005))=B12)*(CALCULATIONS!C6:C5005="Men")*(CALCULATIONS!O6:O5005)) -> 271677.45 | D12: =SUMPRODUCT((MONTH(DATEVALUE(CALCULATIONS!E6:E5005))=B12)*(CALCULATIONS!C6:C5005="Women")*(CALCULATIONS!O6:O5005)) -> 268970.45 | E12: =SUMPRODUCT((MONTH(DATEVALUE(CALCULATIONS!E6:E5005))=B12)*(CALCULATIONS!C6:C5005="Kids")*(CALCULATIONS!O6:O5005)) -> 145439.71 | F12: =SUM(C12:E12) -> 686087.61
A13: Nov | B13: 11 | C13: =SUMPRODUCT((MONTH(DATEVALUE(CALCULATIONS!E6:E5005))=B13)*(CALCULATIONS!C6:C5005="Men")*(CALCULATIONS!O6:O5005)) -> 268655.88 | D13: =SUMPRODUCT((MONTH(DATEVALUE(CALCULATIONS!E6:E5005))=B13)*(CALCULATIONS!C6:C5005="Women")*(CALCULATIONS!O6:O5005)) -> 225320.57 | E13: =SUMPRODUCT((MONTH(DATEVALUE(CALCULATIONS!E6:E5005))=B13)*(CALCULATIONS!C6:C5005="Kids")*(CALCULATIONS!O6:O5005)) -> 100001.98 | F13: =SUM(C13:E13) -> 593978.43
A14: Dec | B14: 12 | C14: =SUMPRODUCT((MONTH(DATEVALUE(CALCULATIONS!E6:E5005))=B14)*(CALCULATIONS!C6:C5005="Men")*(CALCULATIONS!O6:O5005)) -> 293079.38 | D14: =SUMPRODUCT((MONTH(DATEVALUE(CALCULATIONS!E6:E5005))=B14)*(CALCULATIONS!C6:C5005="Women")*(CALCULATIONS!O6:O5005)) -> 279173.49 | E14: =SUMPRODUCT((MONTH(DATEVALUE(CALCULATIONS!E6:E5005))=B14)*(CALCULATIONS!C6:C5005="Kids")*(CALCULATIONS!O6:O5005)) -> 178431.45 | F14: =SUM(C14:E14) -> 750684.31
A17: P2: RETURN RATE BY REGION
A18: Region | B18: Total Orders | C18: Returns | D18: Return Rate %
A19: Bagmati | B19: =COUNTIF(CALCULATIONS!G6:G5005,A19) -> 1477 | C19: =SUMPRODUCT((CALCULATIONS!G6:G5005=A19)*(CALCULATIONS!J6:J5005="Yes")) -> 264 | D19: =IF(B19>0,C19/B19,0) -> 0.17874069
A20: Madhesh | B20: =COUNTIF(CALCULATIONS!G6:G5005,A20) -> 990 | C20: =SUMPRODUCT((CALCULATIONS!G6:G5005=A20)*(CALCULATIONS!J6:J5005="Yes")) -> 165 | D20: =IF(B20>0,C20/B20,0) -> 0.16666667
A21: Gandaki | B21: =COUNTIF(CALCULATIONS!G6:G5005,A21) -> 697 | C21: =SUMPRODUCT((CALCULATIONS!G6:G5005=A21)*(CALCULATIONS!J6:J5005="Yes")) -> 136 | D21: =IF(B21>0,C21/B21,0) -> 0.19512195
A22: Lumbini | B22: =COUNTIF(CALCULATIONS!G6:G5005,A22) -> 764 | C22: =SUMPRODUCT((CALCULATIONS!G6:G5005=A22)*(CALCULATIONS!J6:J5005="Yes")) -> 143 | D22: =IF(B22>0,C22/B22,0) -> 0.18717277
A23: Karnali | B23: =COUNTIF(CALCULATIONS!G6:G5005,A23) -> 516 | C23: =SUMPRODUCT((CALCULATIONS!G6:G5005=A23)*(CALCULATIONS!J6:J5005="Yes")) -> 106 | D23: =IF(B23>0,C23/B23,0) -> 0.20542636
A24: Sudurpashchim | B24: =COUNTIF(CALCULATIONS!G6:G5005,A24) -> 556 | C24: =SUMPRODUCT((CALCULATIONS!G6:G5005=A24)*(CALCULATIONS!J6:J5005="Yes")) -> 92 | D24: =IF(B24>0,C24/B24,0) -> 0.16546763
A27: P3: TOP-SKU PARETO (all 30 SKUs)
A28: SKU | B28: Category | C28: Total Revenue | D28: Revenue Rank | E28: Cumulative Rev | F28: Cumulative %
A29: MEN-SHIRT-001 | B29: Men | C29: =SUMPRODUCT((CALCULATIONS!D6:D5005=A29)*(CALCULATIONS!L6:L5005)) -> 1339959.9 | D29: =RANK(C29,C29:C58,0) -> 9 | E29: =IF(D29=1,C29,C29+IFERROR(INDEX(E29:E58,MATCH(D29-1,D29:D58,0)),0)) -> 12703583 | F29: =IF(SUM(C29:C58)>0,E29/SUM($C$29:$C$58),0) -> 0.39041469
A30: MEN-SHIRT-002 | B30: Men | C30: =SUMPRODUCT((CALCULATIONS!D6:D5005=A30)*(CALCULATIONS!L6:L5005)) -> 1251201.6 | D30: =RANK(C30,C29:C58,0) -> 15 | E30: =IF(D30=1,C30,C30+IFERROR(INDEX(E29:E58,MATCH(D30-1,D29:D58,0)),0)) -> 20401510 | F30: =IF(SUM(C29:C58)>0,E30/SUM($C$29:$C$58),0) -> 0.62699236
A31: MEN-JEANS-001 | B31: Men | C31: =SUMPRODUCT((CALCULATIONS!D6:D5005=A31)*(CALCULATIONS!L6:L5005)) -> 1324356.6 | D31: =RANK(C31,C29:C58,0) -> 10 | E31: =IF(D31=1,C31,C31+IFERROR(INDEX(E29:E58,MATCH(D31-1,D29:D58,0)),0)) -> 14027939 | F31: =IF(SUM(C29:C58)>0,E31/SUM($C$29:$C$58),0) -> 0.43111567
A32: MEN-JEANS-002 | B32: Men | C32: =SUMPRODUCT((CALCULATIONS!D6:D5005=A32)*(CALCULATIONS!L6:L5005)) -> 1322694.1 | D32: =RANK(C32,C29:C58,0) -> 11 | E32: =IF(D32=1,C32,C32+IFERROR(INDEX(E29:E58,MATCH(D32-1,D29:D58,0)),0)) -> 15350633 | F32: =IF(SUM(C29:C58)>0,E32/SUM($C$29:$C$58),0) -> 0.47176556
A33: MEN-JACKET-001 | B33: Men | C33: =SUMPRODUCT((CALCULATIONS!D6:D5005=A33)*(CALCULATIONS!L6:L5005)) -> 1209510.2 | D33: =RANK(C33,C29:C58,0) -> 16 | E33: =IF(D33=1,C33,C33+IFERROR(INDEX(E29:E58,MATCH(D33-1,D29:D58,0)),0)) -> 21611020 | F33: =IF(SUM(C29:C58)>0,E33/SUM($C$29:$C$58),0) -> 0.6641638
A34: MEN-SUIT-001 | B34: Men | C34: =SUMPRODUCT((CALCULATIONS!D6:D5005=A34)*(CALCULATIONS!L6:L5005)) -> 1158026.4 | D34: =RANK(C34,C29:C58,0) -> 17 | E34: =IF(D34=1,C34,C34+IFERROR(INDEX(E29:E58,MATCH(D34-1,D29:D58,0)),0)) -> 22769047 | F34: =IF(SUM(C29:C58)>0,E34/SUM($C$29:$C$58),0) -> 0.69975302
A35: MEN-POLO-001 | B35: Men | C35: =SUMPRODUCT((CALCULATIONS!D6:D5005=A35)*(CALCULATIONS!L6:L5005)) -> 1432652.9 | D35: =RANK(C35,C29:C58,0) -> 4 | E35: =IF(D35=1,C35,C35+IFERROR(INDEX(E29:E58,MATCH(D35-1,D29:D58,0)),0)) -> 5813968.1 | F35: =IF(SUM(C29:C58)>0,E35/SUM($C$29:$C$58),0) -> 0.17867862
A36: MEN-TSHIRT-001 | B36: Men | C36: =SUMPRODUCT((CALCULATIONS!D6:D5005=A36)*(CALCULATIONS!L6:L5005)) -> 1270701.2 | D36: =RANK(C36,C29:C58,0) -> 13 | E36: =IF(D36=1,C36,C36+IFERROR(INDEX(E29:E58,MATCH(D36-1,D29:D58,0)),0)) -> 17898055 | F36: =IF(SUM(C29:C58)>0,E36/SUM($C$29:$C$58),0) -> 0.55005455
A37: MEN-CHINO-001 | B37: Men | C37: =SUMPRODUCT((CALCULATIONS!D6:D5005=A37)*(CALCULATIONS!L6:L5005)) -> 1373951.6 | D37: =RANK(C37,C29:C58,0) -> 7 | E37: =IF(D37=1,C37,C37+IFERROR(INDEX(E29:E58,MATCH(D37-1,D29:D58,0)),0)) -> 10007198 | F37: =IF(SUM(C29:C58)>0,E37/SUM($C$29:$C$58),0) -> 0.30754767
A38: MEN-KURTA-001 | B38: Men | C38: =SUMPRODUCT((CALCULATIONS!D6:D5005=A38)*(CALCULATIONS!L6:L5005)) -> 1466587.3 | D38: =RANK(C38,C29:C58,0) -> 2 | E38: =IF(D38=1,C38,C38+IFERROR(INDEX(E29:E58,MATCH(D38-1,D29:D58,0)),0)) -> 2936661.4 | F38: =IF(SUM(C29:C58)>0,E38/SUM($C$29:$C$58),0) -> 0.090251371
A39: WOM-KURTA-001 | B39: Women | C39: =SUMPRODUCT((CALCULATIONS!D6:D5005=A39)*(CALCULATIONS!L6:L5005)) -> 1123501.5 | D39: =RANK(C39,C29:C58,0) -> 20 | E39: =IF(D39=1,C39,C39+IFERROR(INDEX(E29:E58,MATCH(D39-1,D29:D58,0)),0)) -> 26172836 | F39: =IF(SUM(C29:C58)>0,E39/SUM($C$29:$C$58),0) -> 0.80436046
A40: WOM-SAREE-001 | B40: Women | C40: =SUMPRODUCT((CALCULATIONS!D6:D5005=A40)*(CALCULATIONS!L6:L5005)) -> 1156323.6 | D40: =RANK(C40,C29:C58,0) -> 18 | E40: =IF(D40=1,C40,C40+IFERROR(INDEX(E29:E58,MATCH(D40-1,D29:D58,0)),0)) -> 23925370 | F40: =IF(SUM(C29:C58)>0,E40/SUM($C$29:$C$58),0) -> 0.7352899
A41: WOM-DRESS-001 | B41: Women | C41: =SUMPRODUCT((CALCULATIONS!D6:D5005=A41)*(CALCULATIONS!L6:L5005)) -> 1431852 | D41: =RANK(C41,C29:C58,0) -> 5 | E41: =IF(D41=1,C41,C41+IFERROR(INDEX(E29:E58,MATCH(D41-1,D29:D58,0)),0)) -> 7245820.1 | F41: =IF(SUM(C29:C58)>0,E41/SUM($C$29:$C$58),0) -> 0.22268321
A42: WOM-TOP-001 | B42: Women | C42: =SUMPRODUCT((CALCULATIONS!D6:D5005=A42)*(CALCULATIONS!L6:L5005)) -> 1252253.7 | D42: =RANK(C42,C29:C58,0) -> 14 | E42: =IF(D42=1,C42,C42+IFERROR(INDEX(E29:E58,MATCH(D42-1,D29:D58,0)),0)) -> 19150309 | F42: =IF(SUM(C29:C58)>0,E42/SUM($C$29:$C$58),0) -> 0.58853962
A43: WOM-JEANS-001 | B43: Women | C43: =SUMPRODUCT((CALCULATIONS!D6:D5005=A43)*(CALCULATIONS!L6:L5005)) -> 1123963.9 | D43: =RANK(C43,C29:C58,0) -> 19 | E43: =IF(D43=1,C43,C43+IFERROR(INDEX(E29:E58,MATCH(D43-1,D29:D58,0)),0)) -> 25049334 | F43: =IF(SUM(C29:C58)>0,E43/SUM($C$29:$C$58),0) -> 0.76983229
A44: WOM-BLOUSE-001 | B44: Women | C44: =SUMPRODUCT((CALCULATIONS!D6:D5005=A44)*(CALCULATIONS!L6:L5005)) -> 1387426.6 | D44: =RANK(C44,C29:C58,0) -> 6 | E44: =IF(D44=1,C44,C44+IFERROR(INDEX(E29:E58,MATCH(D44-1,D29:D58,0)),0)) -> 8633246.7 | F44: =IF(SUM(C29:C58)>0,E44/SUM($C$29:$C$58),0) -> 0.2653225
...

Sheet ANOMALIES
A1: 🚨 SAGARMATHA STORE — ANOMALY REPORT: Late Delivery (>10 Days) AND Negative Profit
A2: Order ID | B2: Category | C2: Region | D2: Order Date | E2: Delivery Date | F2: Delivery Days | G2: Sales Amount | H2: Discount % | I2: True Profit (NPR)
A3: ⚠ This sheet uses helper columns. Scroll right to see full detail. Data auto-filters for: Delivery Days > 10 AND True Profit < 0
A5: Instructions: In Excel desktop, insert a PivotTable from CALCULATIONS sheet filtered on Delivery Days > 10 AND True Profit < 0. Or use the SUMMARY_COUNTS from PIVOT_DATA!P5 section above. The counts and totals are already computed in PIVOT_DATA sheet (P5 section).

Sheet DASHBOARD
A1: SAGARMATHA STORE | SALES & PROFIT ANALYTICS DASHBOARD | FY 2024
A5: TOTAL ORDERS | G5: TOTAL REVENUE (NPR) | M5: TOTAL PROFIT (NPR) | S5: OVERALL RETURN RATE
A6: =COUNTA(CALCULATIONS!A6:A5005) -> 5000 | G6: =SUM(CALCULATIONS!L6:L5005) -> 32538690 | M6: =SUM(CALCULATIONS!O6:O5005) -> 8156967.6 | S6: =COUNTIF(CALCULATIONS!J6:J5005,"Yes")/5000 -> 0.1812
A10: 📈 MONTHLY PROFIT TREND BY CATEGORY
A11: Month | B11: Men Profit | C11: Women Profit | D11: Kids Profit | E11: Total
A12: Jan | B12: =PIVOT_DATA!C3 -> 262566.42 | C12: =PIVOT_DATA!D3 -> 272034.54 | D12: =PIVOT_DATA!E3 -> 133339.69 | E12: =PIVOT_DATA!F3 -> 667940.65
A13: Feb | B13: =PIVOT_DATA!C4 -> 284157.46 | C13: =PIVOT_DATA!D4 -> 280479.8 | D13: =PIVOT_DATA!E4 -> 122271.79 | E13: =PIVOT_DATA!F4 -> 686909.05
A14: Mar | B14: =PIVOT_DATA!C5 -> 286144.58 | C14: =PIVOT_DATA!D5 -> 281468.46 | D14: =PIVOT_DATA!E5 -> 151507.77 | E14: =PIVOT_DATA!F5 -> 719120.81
A15: Apr | B15: =PIVOT_DATA!C6 -> 235373.27 | C15: =PIVOT_DATA!D6 -> 249010.28 | D15: =PIVOT_DATA!E6 -> 101519.94 | E15: =PIVOT_DATA!F6 -> 585903.49
A16: May | B16: =PIVOT_DATA!C7 -> 260362.18 | C16: =PIVOT_DATA!D7 -> 285885.12 | D16: =PIVOT_DATA!E7 -> 164473.71 | E16: =PIVOT_DATA!F7 -> 710721.01
A17: Jun | B17: =PIVOT_DATA!C8 -> 261906.92 | C17: =PIVOT_DATA!D8 -> 283600.75 | D17: =PIVOT_DATA!E8 -> 129274.41 | E17: =PIVOT_DATA!F8 -> 674782.08
A18: Jul | B18: =PIVOT_DATA!C9 -> 325340.9 | C18: =PIVOT_DATA!D9 -> 290574.24 | D18: =PIVOT_DATA!E9 -> 171872.71 | E18: =PIVOT_DATA!F9 -> 787787.85
A19: Aug | B19: =PIVOT_DATA!C10 -> 295694.59 | C19: =PIVOT_DATA!D10 -> 295161.99 | D19: =PIVOT_DATA!E10 -> 119492.58 | E19: =PIVOT_DATA!F10 -> 710349.16
A20: Sep | B20: =PIVOT_DATA!C11 -> 239569.31 | C20: =PIVOT_DATA!D11 -> 240357.1 | D20: =PIVOT_DATA!E11 -> 102776.74 | E20: =PIVOT_DATA!F11 -> 582703.15
A21: Oct | B21: =PIVOT_DATA!C12 -> 271677.45 | C21: =PIVOT_DATA!D12 -> 268970.45 | D21: =PIVOT_DATA!E12 -> 145439.71 | E21: =PIVOT_DATA!F12 -> 686087.61
A22: Nov | B22: =PIVOT_DATA!C13 -> 268655.88 | C22: =PIVOT_DATA!D13 -> 225320.57 | D22: =PIVOT_DATA!E13 -> 100001.98 | E22: =PIVOT_DATA!F13 -> 593978.43
A23: Dec | B23: =PIVOT_DATA!C14 -> 293079.38 | C23: =PIVOT_DATA!D14 -> 279173.49 | D23: =PIVOT_DATA!E14 -> 178431.45 | E23: =PIVOT_DATA!F14 -> 750684.31
A25: 🔴 RETURN RATE BY REGION
A26: Region | B26: Orders | C26: Returns | D26: Return Rate % | E26: Trend
A27: =PIVOT_DATA!A19 -> Bagmati | B27: =PIVOT_DATA!B19 -> 1477 | C27: =PIVOT_DATA!C19 -> 264 | D27: =PIVOT_DATA!D19 -> 0.17874069 | E27: =PIVOT_DATA!O63 -> ⬆ RISING
A28: =PIVOT_DATA!A20 -> Madhesh | B28: =PIVOT_DATA!B20 -> 990 | C28: =PIVOT_DATA!C20 -> 165 | D28: =PIVOT_DATA!D20 -> 0.16666667 | E28: =PIVOT_DATA!O64 -> ⬇ STABLE
A29: =PIVOT_DATA!A21 -> Gandaki | B29: =PIVOT_DATA!B21 -> 697 | C29: =PIVOT_DATA!C21 -> 136 | D29: =PIVOT_DATA!D21 -> 0.19512195 | E29: =PIVOT_DATA!O65 -> ⬇ STABLE
A30: =PIVOT_DATA!A22 -> Lumbini | B30: =PIVOT_DATA!B22 -> 764 | C30: =PIVOT_DATA!C22 -> 143 | D30: =PIVOT_DATA!D22 -> 0.18717277 | E30: =PIVOT_DATA!O66 -> ⬇ STABLE
A31: =PIVOT_DATA!A23 -> Karnali | B31: =PIVOT_DATA!B23 -> 516 | C31: =PIVOT_DATA!C23 -> 106 | D31: =PIVOT_DATA!D23 -> 0.20542636 | E31: =PIVOT_DATA!O67 -> ⬆ RISING
A32: =PIVOT_DATA!A24 -> Sudurpashchim | B32: =PIVOT_DATA!B24 -> 556 | C32: =PIVOT_DATA!C24 -> 92 | D32: =PIVOT_DATA!D24 -> 0.16546763 | E32: =PIVOT_DATA!O68 -> ⬇ STABLE
A36: 🏆 TOP 10 SKUs — PARETO ANALYSIS (80% Revenue)
A37: Rank | B37: SKU | C37: Category | D37: Revenue (NPR) | E37: Cumulative % | F37: 80% Line
A38: 1 | B38: =IFERROR(INDEX(PIVOT_DATA!A29:A58,MATCH(1,PIVOT_DATA!D29:D58,0)),"") -> WOM-SUIT-001 | C38: =IFERROR(INDEX(PIVOT_DATA!B29:B58,MATCH(1,PIVOT_DATA!D29:D58,0)),"") -> Women | D38: =IFERROR(INDEX(PIVOT_DATA!C29:C58,MATCH(1,PIVOT_DATA!D29:D58,0)),0) -> 1470074.2 | E38: =IFERROR(INDEX(PIVOT_DATA!F29:F58,MATCH(1,PIVOT_DATA!D29:D58,0)),0) -> 0.045179267 | F38: 0.8
A39: 2 | B39: =IFERROR(INDEX(PIVOT_DATA!A29:A58,MATCH(2,PIVOT_DATA!D29:D58,0)),"") -> MEN-KURTA-001 | C39: =IFERROR(INDEX(PIVOT_DATA!B29:B58,MATCH(2,PIVOT_DATA!D29:D58,0)),"") -> Men | D39: =IFERROR(INDEX(PIVOT_DATA!C29:C58,MATCH(2,PIVOT_DATA!D29:D58,0)),0) -> 1466587.3 | E39: =IFERROR(INDEX(PIVOT_DATA!F29:F58,MATCH(2,PIVOT_DATA!D29:D58,0)),0) -> 0.090251371 | F39: 0.8
A40: 3 | B40: =IFERROR(INDEX(PIVOT_DATA!A29:A58,MATCH(3,PIVOT_DATA!D29:D58,0)),"") -> WOM-SCARF-001 | C40: =IFERROR(INDEX(PIVOT_DATA!B29:B58,MATCH(3,PIVOT_DATA!D29:D58,0)),"") -> Women | D40: =IFERROR(INDEX(PIVOT_DATA!C29:C58,MATCH(3,PIVOT_DATA!D29:D58,0)),0) -> 1444653.8 | E40: =IFERROR(INDEX(PIVOT_DATA!F29:F58,MATCH(3,PIVOT_DATA!D29:D58,0)),0) -> 0.1346494 | F40: 0.8
A41: 4 | B41: =IFERROR(INDEX(PIVOT_DATA!A29:A58,MATCH(4,PIVOT_DATA!D29:D58,0)),"") -> MEN-POLO-001 | C41: =IFERROR(INDEX(PIVOT_DATA!B29:B58,MATCH(4,PIVOT_DATA!D29:D58,0)),"") -> Men | D41: =IFERROR(INDEX(PIVOT_DATA!C29:C58,MATCH(4,PIVOT_DATA!D29:D58,0)),0) -> 1432652.9 | E41: =IFERROR(INDEX(PIVOT_DATA!F29:F58,MATCH(4,PIVOT_DATA!D29:D58,0)),0) -> 0.17867862 | F41: 0.8
A42: 5 | B42: =IFERROR(INDEX(PIVOT_DATA!A29:A58,MATCH(5,PIVOT_DATA!D29:D58,0)),"") -> WOM-DRESS-001 | C42: =IFERROR(INDEX(PIVOT_DATA!B29:B58,MATCH(5,PIVOT_DATA!D29:D58,0)),"") -> Women | D42: =IFERROR(INDEX(PIVOT_DATA!C29:C58,MATCH(5,PIVOT_DATA!D29:D58,0)),0) -> 1431852 | E42: =IFERROR(INDEX(PIVOT_DATA!F29:F58,MATCH(5,PIVOT_DATA!D29:D58,0)),0) -> 0.22268321 | F42: 0.8
A43: 6 | B43: =IFERROR(INDEX(PIVOT_DATA!A29:A58,MATCH(6,PIVOT_DATA!D29:D58,0)),"") -> WOM-BLOUSE-001 | C43: =IFERROR(INDEX(PIVOT_DATA!B29:B58,MATCH(6,PIVOT_DATA!D29:D58,0)),"") -> Women | D43: =IFERROR(INDEX(PIVOT_DATA!C29:C58,MATCH(6,PIVOT_DATA!D29:D58,0)),0) -> 1387426.6 | E43: =IFERROR(INDEX(PIVOT_DATA!F29:F58,MATCH(6,PIVOT_DATA!D29:D58,0)),0) -> 0.2653225 | F43: 0.8
A44: 7 | B44: =IFERROR(INDEX(PIVOT_DATA!A29:A58,MATCH(7,PIVOT_DATA!D29:D58,0)),"") -> MEN-CHINO-001 | C44: =IFERROR(INDEX(PIVOT_DATA!B29:B58,MATCH(7,PIVOT_DATA!D29:D58,0)),"") -> Men | D44: =IFERROR(INDEX(PIVOT_DATA!C29:C58,MATCH(7,PIVOT_DATA!D29:D58,0)),0) -> 1373951.6 | E44: =IFERROR(INDEX(PIVOT_DATA!F29:F58,MATCH(7,PIVOT_DATA!D29:D58,0)),0) -> 0.30754767 | F44: 0.8
A45: 8 | B45: =IFERROR(INDEX(PIVOT_DATA!A29:A58,MATCH(8,PIVOT_DATA!D29:D58,0)),"") -> WOM-LEHENGA-001 | C45: =IFERROR(INDEX(PIVOT_DATA!B29:B58,MATCH(8,PIVOT_DATA!D29:D58,0)),"") -> Women | D45: =IFERROR(INDEX(PIVOT_DATA!C29:C58,MATCH(8,PIVOT_DATA!D29:D58,0)),0) -> 1356424.6 | E45: =IFERROR(INDEX(PIVOT_DATA!F29:F58,MATCH(8,PIVOT_DATA!D29:D58,0)),0) -> 0.34923418 | F45: 0.8
A46: 9 | B46: =IFERROR(INDEX(PIVOT_DATA!A29:A58,MATCH(9,PIVOT_DATA!D29:D58,0)),"") -> MEN-SHIRT-001 | C46: =IFERROR(INDEX(PIVOT_DATA!B29:B58,MATCH(9,PIVOT_DATA!D29:D58,0)),"") -> Men | D46: =IFERROR(INDEX(PIVOT_DATA!C29:C58,MATCH(9,PIVOT_DATA!D29:D58,0)),0) -> 1339959.9 | E46: =IFERROR(INDEX(PIVOT_DATA!F29:F58,MATCH(9,PIVOT_DATA!D29:D58,0)),0) -> 0.39041469 | F46: 0.8
A47: 10 | B47: =IFERROR(INDEX(PIVOT_DATA!A29:A58,MATCH(10,PIVOT_DATA!D29:D58,0)),"") -> MEN-JEANS-001 | C47: =IFERROR(INDEX(PIVOT_DATA!B29:B58,MATCH(10,PIVOT_DATA!D29:D58,0)),"") -> Men | D47: =IFERROR(INDEX(PIVOT_DATA!C29:C58,MATCH(10,PIVOT_DATA!D29:D58,0)),0) -> 1324356.6 | E47: =IFERROR(INDEX(PIVOT_DATA!F29:F58,MATCH(10,PIVOT_DATA!D29:D58,0)),0) -> 0.43111567 | F47: 0.8
A49: ⚠ ANOMALY SUMMARY
A50: Anomaly Orders (Delay>10d & Profit<0) | D50: =PIVOT_DATA!B73 -> 29
A51: % of Total Orders | D51: =PIVOT_DATA!B74 -> 0.0058
...

Sheet GUIDE
A1: SAGARMATHA STORE — WORKBOOK GUIDE & PERFORMANCE TIPS
A3: SHEET STRUCTURE
A4: 1. RAW_DATA – Source data (5K sample; replace with full 500K export)
A5: 2. CALCULATIONS – Profit engine: effective revenue, base cost, return cost, true profit
A6: 3. PIVOT_DATA – SUMPRODUCT aggregations feeding the dashboard (no PivotTable needed)
A7: 4. DASHBOARD – Visual KPIs, charts, Pareto, anomaly callouts
A8: 5. ANOMALIES – Instruction sheet; use PIVOT_DATA P5 section for counts
A9: 6. GUIDE – This sheet
A11: PROFIT FORMULA (per order)
A12: Effective Revenue = Sales Amount × (1 – Discount% / 100)
A13: Base Cost = Sales Amount × 60%
A14: Return Cost = Sales Amount × 20% (only when Return = Yes)
... A43: Dashboard shows top 10 with cumulative % line — visually identifies 80% threshold
